Workbook

Sheet Quote R1
A1: NOKU | B1: Umang - Sample House - Furniture costing | F1: 46074
A2: Sr. No | B2: Item | C2: Name & Size | D2: Qty | E2: Rate | F2: Amount
A3: 1 | C3: =MasterSummary!A2 & CHAR(10) & MasterSummary!B2 & "cm, " & MasterSummary!C2 & "cm, " & MasterSummary!D2 & "cm, SH-" & MasterSummary!E2 & "cm" -> Barstool 01 B1 48cm, 50cm, 100cm, SH-75cm | D3: 3 | E3: =MasterSummary!U2 -> 19000 | F3: =D3*E3 -> 57000
A4: 2 | C4: =MasterSummary!A3 & CHAR(10) & MasterSummary!B3 & "cm, " & MasterSummary!C3 & "cm, " & MasterSummary!D3 & "cm, SH-" & MasterSummary!E3 & "cm" -> Barstool 03 A1 40cm, 44cm, 101cm, SH-75cm | D4: 1 | E4: =MasterSummary!U3 -> 20000 | F4: =D4*E4 -> 20000
A5: 3 | C5: =MasterSummary!A4 & CHAR(10) & MasterSummary!B4 & "cm, " & MasterSummary!C4 & "cm, " & MasterSummary!D4 & "cm, SH-" & MasterSummary!E4 & "cm" -> Barstool 11 A1 55cm, 54cm, 102cm, SH-75cm | D5: 2 | E5: =MasterSummary!U4 -> 27000 | F5: =D5*E5 -> 54000
A6: 4 | C6: =MasterSummary!A5 & CHAR(10) & MasterSummary!B5 & "cm, " & MasterSummary!C5 & "cm, " & MasterSummary!D5 & "cm, SH-" & MasterSummary!E5 & "cm" -> Bed 01 A1 194cm, 210cm, 92cm, SH-50cm | D6: 1 | E6: =MasterSummary!U5 -> 105000 | F6: =D6*E6 -> 105000
A7: 5 | C7: =MasterSummary!A6 & CHAR(10) & MasterSummary!B6 & "cm, " & MasterSummary!C6 & "cm, " & MasterSummary!D6 & "cm, SH-" & MasterSummary!E6 & "cm" -> Bed 04 A1 204cm, 220cm, 197cm, SH-48cm | D7: 1 | E7: =MasterSummary!U6 -> 117000 | F7: =D7*E7 -> 117000
A8: 6 | C8: =MasterSummary!A7 & CHAR(10) & MasterSummary!B7 & "cm, " & MasterSummary!C7 & "cm, " & MasterSummary!D7 & "cm, SH-" & MasterSummary!E7 & "cm" -> Bed 27 A1 288cm, 217cm, 110cm, SH-48cm | D8: 1 | E8: =MasterSummary!U7 -> 146000 | F8: =D8*E8 -> 146000
A9: 7 | C9: =MasterSummary!A8 & CHAR(10) & MasterSummary!B8 & "cm, " & MasterSummary!C8 & "cm, " & MasterSummary!D8 & "cm, SH-" & MasterSummary!E8 & "cm" -> Bed 47 A1 196cm, 208cm, 112cm, SH-50cm | D9: 1 | E9: =MasterSummary!U8 -> 103000 | F9: =D9*E9 -> 103000
A10: 8 | C10: =MasterSummary!A9 & CHAR(10) & MasterSummary!B9 & "cm, " & MasterSummary!C9 & "cm, " & MasterSummary!D9 & "cm, SH-" & MasterSummary!E9 & "cm" -> Bench 03 A1 141cm, 38cm, 45cm, SH-cm | D10: 2 | E10: =MasterSummary!U9 -> 25000 | F10: =D10*E10 -> 50000
A11: 9 | C11: =MasterSummary!A10 & CHAR(10) & MasterSummary!B10 & "cm, " & MasterSummary!C10 & "cm, " & MasterSummary!D10 & "cm, SH-" & MasterSummary!E10 & "cm" -> Bench 14 A1 cm, cm, cm, SH-cm | D11: 1 | E11: =MasterSummary!U10 -> 50000 | F11: =D11*E11 -> 50000
A12: 10 | C12: =MasterSummary!A11 & CHAR(10) & MasterSummary!B11 & "cm, " & MasterSummary!C11 & "cm, " & MasterSummary!D11 & "cm, SH-" & MasterSummary!E11 & "cm" -> Bench 20 B1 158cm, 64cm, 70cm, SH-45cm | E12: =MasterSummary!U11 -> 38000 | F12: =D12*E12 -> 0
A13: 11 | C13: =MasterSummary!A12 & CHAR(10) & MasterSummary!B12 & "cm, " & MasterSummary!C12 & "cm, " & MasterSummary!D12 & "cm, SH-" & MasterSummary!E12 & "cm" -> Centre Table 02 A1 76cm, 76cm, 36cm, SH-cm | D13: 1 | E13: =MasterSummary!U12 -> 22000 | F13: =D13*E13 -> 22000
A14: 12 | C14: =MasterSummary!A13 & CHAR(10) & MasterSummary!B13 & "cm, " & MasterSummary!C13 & "cm, " & MasterSummary!D13 & "cm, SH-" & MasterSummary!E13 & "cm" -> Centre Table 13 A1 129cm, 76cm, 40cm, SH-cm | D14: 1 | E14: =MasterSummary!U13 -> 32000 | F14: =D14*E14 -> 32000
A15: 13 | C15: =MasterSummary!A14 & CHAR(10) & MasterSummary!B14 & "cm, " & MasterSummary!C14 & "cm, " & MasterSummary!D14 & "cm, SH-" & MasterSummary!E14 & "cm" -> Centre Table 23 A1 102cm, 68cm, 45cm, SH-cm | D15: 1 | E15: =MasterSummary!U14 -> 29000 | F15: =D15*E15 -> 29000
A16: 14 | C16: =MasterSummary!A15 & CHAR(10) & MasterSummary!B15 & "cm, " & MasterSummary!C15 & "cm, " & MasterSummary!D15 & "cm, SH-" & MasterSummary!E15 & "cm" -> Chair 06 A1 65cm, 83cm, 91cm, SH-39cm | D16: 2 | E16: =MasterSummary!U15 -> 36000 | F16: =D16*E16 -> 72000
A17: 15 | C17: =MasterSummary!A16 & CHAR(10) & MasterSummary!B16 & "cm, " & MasterSummary!C16 & "cm, " & MasterSummary!D16 & "cm, SH-" & MasterSummary!E16 & "cm" -> Chair 07 A1 65cm, 83cm, 91cm, SH-39cm | D17: 1 | E17: =MasterSummary!U16 -> 31000 | F17: =D17*E17 -> 31000
A18: 16 | C18: =MasterSummary!A17 & CHAR(10) & MasterSummary!B17 & "cm, " & MasterSummary!C17 & "cm, " & MasterSummary!D17 & "cm, SH-" & MasterSummary!E17 & "cm" -> Chair 12 C1 54cm, 61cm, 89cm, SH-45cm | D18: 1 | E18: =MasterSummary!U17 -> 27000 | F18: =D18*E18 -> 27000
A19: 17 | C19: =MasterSummary!A18 & CHAR(10) & MasterSummary!B18 & "cm, " & MasterSummary!C18 & "cm, " & MasterSummary!D18 & "cm, SH-" & MasterSummary!E18 & "cm" -> Chair 42 A1 62cm, 76cm, 82cm, SH-41cm | D19: 2 | E19: =MasterSummary!U18 -> 38000 | F19: =D19*E19 -> 76000
A20: 18 | C20: =MasterSummary!A19 & CHAR(10) & MasterSummary!B19 & "cm, " & MasterSummary!C19 & "cm, " & MasterSummary!D19 & "cm, SH-" & MasterSummary!E19 & "cm" -> Chair 27 A1 67cm, 77cm, 70cm, SH-37cm | D20: 2 | E20: =MasterSummary!U19 -> 26000 | F20: =D20*E20 -> 52000
A21: 19 | C21: =MasterSummary!A20 & CHAR(10) & MasterSummary!B20 & "cm, " & MasterSummary!C20 & "cm, " & MasterSummary!D20 & "cm, SH-" & MasterSummary!E20 & "cm" -> Chair 44 C1 45cm, 52cm, 79cm, SH-45cm | D21: 2 | E21: =MasterSummary!U20 -> 20000 | F21: =D21*E21 -> 40000
A22: 20 | C22: =MasterSummary!A21 & CHAR(10) & MasterSummary!B21 & "cm, " & MasterSummary!C21 & "cm, " & MasterSummary!D21 & "cm, SH-" & MasterSummary!E21 & "cm" -> Chair 05 A1 44cm, 51cm, 87cm, SH-45cm | E22: =MasterSummary!U21 -> 17000 | F22: =D22*E22 -> 0
A23: 21 | C23: =MasterSummary!A22 & CHAR(10) & MasterSummary!B22 & "cm, " & MasterSummary!C22 & "cm, " & MasterSummary!D22 & "cm, SH-" & MasterSummary!E22 & "cm" -> Chair 09 A1 50cm, 50cm, 77cm, SH-45cm | D23: 2 | E23: =MasterSummary!U22 -> 21000 | F23: =D23*E23 -> 42000
A24: 22 | C24: =MasterSummary!A23 & CHAR(10) & MasterSummary!B23 & "cm, " & MasterSummary!C23 & "cm, " & MasterSummary!D23 & "cm, SH-" & MasterSummary!E23 & "cm" -> Dining Table 03 A1 198cm, 92cm, 75cm, SH-cm | D24: 1 | E24: =MasterSummary!U23 -> 78000 | F24: =D24*E24 -> 78000
A25: 23 | C25: =MasterSummary!A24 & CHAR(10) & MasterSummary!B24 & "cm, " & MasterSummary!C24 & "cm, " & MasterSummary!D24 & "cm, SH-" & MasterSummary!E24 & "cm" -> Side Table 01 A1 48cm, 48cm, 49cm, SH-cm | D25: 2 | E25: =MasterSummary!U24 -> 21000 | F25: =D25*E25 -> 42000
A26: 24 | C26: =MasterSummary!A25 & CHAR(10) & MasterSummary!B25 & "cm, " & MasterSummary!C25 & "cm, " & MasterSummary!D25 & "cm, SH-" & MasterSummary!E25 & "cm" -> Side Table 02 A1 40cm, 40cm, 53cm, SH-cm | D26: 1 | E26: =MasterSummary!U25 -> 11000 | F26: =D26*E26 -> 11000
A27: 25 | C27: =MasterSummary!A26 & CHAR(10) & MasterSummary!B26 & "cm, " & MasterSummary!C26 & "cm, " & MasterSummary!D26 & "cm, SH-" & MasterSummary!E26 & "cm" -> Side Table 02 C1 45cm, 45cm, 53cm, SH-cm | D27: 1 | E27: =MasterSummary!U26 -> 12000 | F27: =D27*E27 -> 12000
A28: 26 | C28: =MasterSummary!A27 & CHAR(10) & MasterSummary!B27 & "cm, " & MasterSummary!C27 & "cm, " & MasterSummary!D27 & "cm, SH-" & MasterSummary!E27 & "cm" -> Side Table 08 B1 56cm, 40cm, 45cm, SH-cm | D28: 2 | E28: =MasterSummary!U27 -> 33000 | F28: =D28*E28 -> 66000
A29: 27 | C29: =MasterSummary!A28 & CHAR(10) & MasterSummary!B28 & "cm, " & MasterSummary!C28 & "cm, " & MasterSummary!D28 & "cm, SH-" & MasterSummary!E28 & "cm" -> Side Table 31 A1 45cm, 45cm, 45cm, SH-cm | D29: 1 | E29: =MasterSummary!U28 -> 10000 | F29: =D29*E29 -> 10000
C30: =MasterSummary!A29 & CHAR(10) & MasterSummary!B29 & "cm, " & MasterSummary!C29 & "cm, " & MasterSummary!D29 & "cm, SH-" & MasterSummary!E29 & "cm" -> Side Table 42 A1 46cm, 41cm, 46cm, SH-cm | D30: 2 | E30: =MasterSummary!U29 -> 30000 | F30: =D30*E30 -> 60000
C31: =MasterSummary!A30 & CHAR(10) & MasterSummary!B30 & "cm, " & MasterSummary!C30 & "cm, " & MasterSummary!D30 & "cm, SH-" & MasterSummary!E30 & "cm" -> Sofa 23 B1 170cm, 84cm, 79cm, SH-43cm | D31: 1 | E31: =MasterSummary!U30 -> 88000 | F31: =D31*E31 -> 88000
C32: =MasterSummary!A31 & CHAR(10) & MasterSummary!B31 & "cm, " & MasterSummary!C31 & "cm, " & MasterSummary!D31 & "cm, SH-" & MasterSummary!E31 & "cm" -> Sofa 28 C1 255cm, 75cm, 84cm, SH-40cm | D32: 1 | E32: =MasterSummary!U31 -> 110000 | F32: =D32*E32 -> 110000
C33: =MasterSummary!A32 & CHAR(10) & MasterSummary!B32 & "cm, " & MasterSummary!C32 & "cm, " & MasterSummary!D32 & "cm, SH-" & MasterSummary!E32 & "cm" -> Sofa 36 A1 268cm, 80cm, 80cm, SH-35cm | D33: 1 | E33: =MasterSummary!U32 -> 106000 | F33: =D33*E33 -> 106000
C34: =MasterSummary!A33 & CHAR(10) & MasterSummary!B33 & "cm, " & MasterSummary!C33 & "cm, " & MasterSummary!D33 & "cm, SH-" & MasterSummary!E33 & "cm" -> Storage 16 A1 150cm, 42cm, 80cm, SH-cm | D34: 1 | E34: =MasterSummary!U33 -> 88000 | F34: =D34*E34 -> 88000
C35: =MasterSummary!A34 & CHAR(10) & MasterSummary!B34 & "cm, " & MasterSummary!C34 & "cm, " & MasterSummary!D34 & "cm, SH-" & MasterSummary!E34 & "cm" -> Storage 29 C1 129cm, 35cm, 80cm, SH-cm | D35: 1 | E35: =MasterSummary!U34 -> 58000 | F35: =D35*E35 -> 58000
C36: =MasterSummary!A35 & CHAR(10) & MasterSummary!B35 & "cm, " & MasterSummary!C35 & "cm, " & MasterSummary!D35 & "cm, SH-" & MasterSummary!E35 & "cm" -> Storage 34 A1 146cm, 40cm, 92cm, SH-cm | D36: 1 | E36: =MasterSummary!U35 -> 88000 | F36: =D36*E36 -> 88000
C37: =MasterSummary!A36 & CHAR(10) & MasterSummary!B36 & "cm, " & MasterSummary!C36 & "cm, " & MasterSummary!D36 & "cm, SH-" & MasterSummary!E36 & "cm" -> Study Table 02 A1 130cm, 60cm, 75cm, SH-cm | D37: 1 | E37: =MasterSummary!U36 -> 47000 | F37: =D37*E37 -> 47000
C38: =MasterSummary!A37 & CHAR(10) & MasterSummary!B37 & "cm, " & MasterSummary!C37 & "cm, " & MasterSummary!D37 & "cm, SH-" & MasterSummary!E37 & "cm" -> Study Table 11 A1 130cm, 60cm, 75cm, SH-cm | D38: 1 | E38: =MasterSummary!U37 -> 55000 | F38: =D38*E38 -> 55000
C39: =MasterSummary!A38 & CHAR(10) & MasterSummary!B38 & "cm, " & MasterSummary!C38 & "cm, " & MasterSummary!D38 & "cm, SH-" & MasterSummary!E38 & "cm" -> Swing 04 A1 153cm, 61cm, 43cm, SH-cm | E39: =MasterSummary!U38 -> 79000 | F39: =D39*E39 -> 0
C40: =MasterSummary!A39 & CHAR(10) & MasterSummary!B39 & "cm, " & MasterSummary!C39 & "cm, " & MasterSummary!D39 & "cm, SH-" & MasterSummary!E39 & "cm" -> TV Console 09 A1 159cm, 45cm, 45cm, SH-cm | D40: 1 | E40: =MasterSummary!U39 -> 70000 | F40: =D40*E40 -> 70000
...

Sheet MasterSummary
A1: Furniture | B1: Dimension | F1: Quantity | G1: Wood | H1: Labour | I1: Polish | J1: Upholstery | K1: Material | L1: Misc. | M1: Transport | N1: OH % | O1: OH | P1: Item Exp | Q1: Total Item Exp | R1: Margin % | S1: Item Margin | T1: Total Margin | U1: Item Rate | V1: Total
A2: Barstool 01 B1 | B2: 48 | C2: 50 | D2: 100 | E2: 75 | F2: 1 | G2: =SUMIFS(TeakCosting!$F:$F,TeakCosting!$A:$A,MasterSummary!$A2,TeakCosting!$B:$B,MasterSummary!G$1) -> 4226.4 | H2: =SUMIFS(TeakCosting!$F:$F,TeakCosting!$A:$A,MasterSummary!$A2,TeakCosting!$B:$B,MasterSummary!H$1) -> 3975 | I2: =SUMIFS(TeakCosting!$F:$F,TeakCosting!$A:$A,MasterSummary!$A2,TeakCosting!$B:$B,MasterSummary!I$1) -> 1440 | J2: =SUMIFS(TeakCosting!$F:$F,TeakCosting!$A:$A,MasterSummary!$A2,TeakCosting!$B:$B,MasterSummary!J$1) -> 2000 | K2: =SUMIFS(TeakCosting!$F:$F,TeakCosting!$A:$A,MasterSummary!$A2,TeakCosting!$B:$B,MasterSummary!K$1) -> 762.5 | L2: =SUMIFS(TeakCosting!$F:$F,TeakCosting!$A:$A,MasterSummary!$A2,TeakCosting!$B:$B,MasterSummary!L$1) -> 1000 | M2: 0 | N2: 0.1 | O2: =SUM(G2:M2)*N2 -> 1340.39 | P2: =SUM(G2:M2)+O2 -> 14744.29 | Q2: =P2*F2 -> 14744.29 | R2: 0.3 | S2: =P2*R2 -> 4423.287 | T2: =S2*F2 -> 4423.287 | U2: =ROUND(P2+S2,-3) -> 19000 | V2: =F2*U2 -> 19000
A3: Barstool 03 A1 | B3: 40 | C3: 44 | D3: 101 | E3: 75 | F3: 1 | G3: =SUMIFS(TeakCosting!$F:$F,TeakCosting!$A:$A,MasterSummary!$A3,TeakCosting!$B:$B,MasterSummary!G$1) -> 4285.1 | H3: =SUMIFS(TeakCosting!$F:$F,TeakCosting!$A:$A,MasterSummary!$A3,TeakCosting!$B:$B,MasterSummary!H$1) -> 4275 | I3: =SUMIFS(TeakCosting!$F:$F,TeakCosting!$A:$A,MasterSummary!$A3,TeakCosting!$B:$B,MasterSummary!I$1) -> 1440 | J3: =SUMIFS(TeakCosting!$F:$F,TeakCosting!$A:$A,MasterSummary!$A3,TeakCosting!$B:$B,MasterSummary!J$1) -> 2000 | K3: =SUMIFS(TeakCosting!$F:$F,TeakCosting!$A:$A,MasterSummary!$A3,TeakCosting!$B:$B,MasterSummary!K$1) -> 762.5 | L3: =SUMIFS(TeakCosting!$F:$F,TeakCosting!$A:$A,MasterSummary!$A3,TeakCosting!$B:$B,MasterSummary!L$1) -> 1000 | M3: 0 | N3: 0.1 | O3: =SUM(G3:M3)*N3 -> 1376.26 | P3: =SUM(G3:M3)+O3 -> 15138.86 | Q3: =P3*F3 -> 15138.86 | R3: 0.3 | S3: =P3*R3 -> 4541.658 | T3: =S3*F3 -> 4541.658 | U3: =ROUND(P3+S3,-3) -> 20000 | V3: =F3*U3 -> 20000
A4: Barstool 11 A1 | B4: 55 | C4: 54 | D4: 102 | E4: 75 | F4: 1 | G4: =SUMIFS(TeakCosting!$F:$F,TeakCosting!$A:$A,MasterSummary!$A4,TeakCosting!$B:$B,MasterSummary!G$1) -> 7748.4 | H4: =SUMIFS(TeakCosting!$F:$F,TeakCosting!$A:$A,MasterSummary!$A4,TeakCosting!$B:$B,MasterSummary!H$1) -> 6700 | I4: =SUMIFS(TeakCosting!$F:$F,TeakCosting!$A:$A,MasterSummary!$A4,TeakCosting!$B:$B,MasterSummary!I$1) -> 1440 | J4: =SUMIFS(TeakCosting!$F:$F,TeakCosting!$A:$A,MasterSummary!$A4,TeakCosting!$B:$B,MasterSummary!J$1) -> 1500 | K4: =SUMIFS(TeakCosting!$F:$F,TeakCosting!$A:$A,MasterSummary!$A4,TeakCosting!$B:$B,MasterSummary!K$1) -> 762.5 | L4: =SUMIFS(TeakCosting!$F:$F,TeakCosting!$A:$A,MasterSummary!$A4,TeakCosting!$B:$B,MasterSummary!L$1) -> 1000 | M4: 0 | N4: 0.1 | O4: =SUM(G4:M4)*N4 -> 1915.09 | P4: =SUM(G4:M4)+O4 -> 21065.99 | Q4: =P4*F4 -> 21065.99 | R4: 0.3 | S4: =P4*R4 -> 6319.797 | T4: =S4*F4 -> 6319.797 | U4: =ROUND(P4+S4,-3) -> 27000 | V4: =F4*U4 -> 27000
A5: Bed 01 A1 | B5: 194 | C5: 210 | D5: 92 | E5: 50 | F5: 1 | G5: =SUMIFS(TeakCosting!$F:$F,TeakCosting!$A:$A,MasterSummary!$A5,TeakCosting!$B:$B,MasterSummary!G$1) -> 36293.5 | H5: =SUMIFS(TeakCosting!$F:$F,TeakCosting!$A:$A,MasterSummary!$A5,TeakCosting!$B:$B,MasterSummary!H$1) -> 14450 | I5: =SUMIFS(TeakCosting!$F:$F,TeakCosting!$A:$A,MasterSummary!$A5,TeakCosting!$B:$B,MasterSummary!I$1) -> 12320 | J5: =SUMIFS(TeakCosting!$F:$F,TeakCosting!$A:$A,MasterSummary!$A5,TeakCosting!$B:$B,MasterSummary!J$1) -> 6000 | K5: =SUMIFS(TeakCosting!$F:$F,TeakCosting!$A:$A,MasterSummary!$A5,TeakCosting!$B:$B,MasterSummary!K$1) -> 3200 | L5: =SUMIFS(TeakCosting!$F:$F,TeakCosting!$A:$A,MasterSummary!$A5,TeakCosting!$B:$B,MasterSummary!L$1) -> 1000 | M5: 0 | N5: 0.1 | O5: =SUM(G5:M5)*N5 -> 7326.35 | P5: =SUM(G5:M5)+O5 -> 80589.85 | Q5: =P5*F5 -> 80589.85 | R5: 0.3 | S5: =P5*R5 -> 24176.955 | T5: =S5*F5 -> 24176.955 | U5: =ROUND(P5+S5,-3) -> 105000 | V5: =F5*U5 -> 105000
A6: Bed 04 A1 | B6: 204 | C6: 220 | D6: 197 | E6: 48 | F6: 1 | G6: =SUMIFS(TeakCosting!$F:$F,TeakCosting!$A:$A,MasterSummary!$A6,TeakCosting!$B:$B,MasterSummary!G$1) -> 44839.5 | H6: =SUMIFS(TeakCosting!$F:$F,TeakCosting!$A:$A,MasterSummary!$A6,TeakCosting!$B:$B,MasterSummary!H$1) -> 11000 | I6: =SUMIFS(TeakCosting!$F:$F,TeakCosting!$A:$A,MasterSummary!$A6,TeakCosting!$B:$B,MasterSummary!I$1) -> 14880 | J6: =SUMIFS(TeakCosting!$F:$F,TeakCosting!$A:$A,MasterSummary!$A6,TeakCosting!$B:$B,MasterSummary!J$1) -> 5400 | K6: =SUMIFS(TeakCosting!$F:$F,TeakCosting!$A:$A,MasterSummary!$A6,TeakCosting!$B:$B,MasterSummary!K$1) -> 4731.25 | L6: =SUMIFS(TeakCosting!$F:$F,TeakCosting!$A:$A,MasterSummary!$A6,TeakCosting!$B:$B,MasterSummary!L$1) -> 1000 | M6: 0 | N6: 0.1 | O6: =SUM(G6:M6)*N6 -> 8185.075 | P6: =SUM(G6:M6)+O6 -> 90035.825 | Q6: =P6*F6 -> 90035.825 | R6: 0.3 | S6: =P6*R6 -> 27010.747 | T6: =S6*F6 -> 27010.747 | U6: =ROUND(P6+S6,-3) -> 117000 | V6: =F6*U6 -> 117000
A7: Bed 27 A1 | B7: 288 | C7: 217 | D7: 110 | E7: 48 | F7: 1 | G7: =SUMIFS(TeakCosting!$F:$F,TeakCosting!$A:$A,MasterSummary!$A7,TeakCosting!$B:$B,MasterSummary!G$1) -> 33118 | H7: =SUMIFS(TeakCosting!$F:$F,TeakCosting!$A:$A,MasterSummary!$A7,TeakCosting!$B:$B,MasterSummary!H$1) -> 14850 | I7: =SUMIFS(TeakCosting!$F:$F,TeakCosting!$A:$A,MasterSummary!$A7,TeakCosting!$B:$B,MasterSummary!I$1) -> 20480 | J7: =SUMIFS(TeakCosting!$F:$F,TeakCosting!$A:$A,MasterSummary!$A7,TeakCosting!$B:$B,MasterSummary!J$1) -> 9900 | K7: =SUMIFS(TeakCosting!$F:$F,TeakCosting!$A:$A,MasterSummary!$A7,TeakCosting!$B:$B,MasterSummary!K$1) -> 22642.397 | L7: =SUMIFS(TeakCosting!$F:$F,TeakCosting!$A:$A,MasterSummary!$A7,TeakCosting!$B:$B,MasterSummary!L$1) -> 1000 | M7: 0 | N7: 0.1 | O7: =SUM(G7:M7)*N7 -> 10199.04 | P7: =SUM(G7:M7)+O7 -> 112189.44 | Q7: =P7*F7 -> 112189.44 | R7: 0.3 | S7: =P7*R7 -> 33656.831 | T7: =S7*F7 -> 33656.831 | U7: =ROUND(P7+S7,-3) -> 146000 | V7: =F7*U7 -> 146000
A8: Bed 47 A1 | B8: 196 | C8: 208 | D8: 112 | E8: 50 | F8: 1 | G8: =SUMIFS(TeakCosting!$F:$F,TeakCosting!$A:$A,MasterSummary!$A8,TeakCosting!$B:$B,MasterSummary!G$1) -> 37559.9 | H8: =SUMIFS(TeakCosting!$F:$F,TeakCosting!$A:$A,MasterSummary!$A8,TeakCosting!$B:$B,MasterSummary!H$1) -> 8925 | I8: =SUMIFS(TeakCosting!$F:$F,TeakCosting!$A:$A,MasterSummary!$A8,TeakCosting!$B:$B,MasterSummary!I$1) -> 12880 | J8: =SUMIFS(TeakCosting!$F:$F,TeakCosting!$A:$A,MasterSummary!$A8,TeakCosting!$B:$B,MasterSummary!J$1) -> 8100 | K8: =SUMIFS(TeakCosting!$F:$F,TeakCosting!$A:$A,MasterSummary!$A8,TeakCosting!$B:$B,MasterSummary!K$1) -> 3896.875 | L8: =SUMIFS(TeakCosting!$F:$F,TeakCosting!$A:$A,MasterSummary!$A8,TeakCosting!$B:$B,MasterSummary!L$1) -> 1000 | M8: 0 | N8: 0.1 | O8: =SUM(G8:M8)*N8 -> 7236.1775 | P8: =SUM(G8:M8)+O8 -> 79597.952 | Q8: =P8*F8 -> 79597.952 | R8: 0.3 | S8: =P8*R8 -> 23879.386 | T8: =S8*F8 -> 23879.386 | U8: =ROUND(P8+S8,-3) -> 103000 | V8: =F8*U8 -> 103000
A9: Bench 03 A1 | B9: 141 | C9: 38 | D9: 45 | F9: 1 | G9: =SUMIFS(TeakCosting!$F:$F,TeakCosting!$A:$A,MasterSummary!$A9,TeakCosting!$B:$B,MasterSummary!G$1) -> 5283 | H9: =SUMIFS(TeakCosting!$F:$F,TeakCosting!$A:$A,MasterSummary!$A9,TeakCosting!$B:$B,MasterSummary!H$1) -> 2700 | I9: =SUMIFS(TeakCosting!$F:$F,TeakCosting!$A:$A,MasterSummary!$A9,TeakCosting!$B:$B,MasterSummary!I$1) -> 1920 | J9: =SUMIFS(TeakCosting!$F:$F,TeakCosting!$A:$A,MasterSummary!$A9,TeakCosting!$B:$B,MasterSummary!J$1) -> 4000 | K9: =SUMIFS(TeakCosting!$F:$F,TeakCosting!$A:$A,MasterSummary!$A9,TeakCosting!$B:$B,MasterSummary!K$1) -> 2806.25 | L9: =SUMIFS(TeakCosting!$F:$F,TeakCosting!$A:$A,MasterSummary!$A9,TeakCosting!$B:$B,MasterSummary!L$1) -> 1000 | M9: 0 | N9: 0.1 | O9: =SUM(G9:M9)*N9 -> 1770.925 | P9: =SUM(G9:M9)+O9 -> 19480.175 | Q9: =P9*F9 -> 19480.175 | R9: 0.3 | S9: =P9*R9 -> 5844.0525 | T9: =S9*F9 -> 5844.0525 | U9: =ROUND(P9+S9,-3) -> 25000 | V9: =F9*U9 -> 25000
A10: Bench 14 A1 | F10: 1 | G10: =SUMIFS(TeakCosting!$F:$F,TeakCosting!$A:$A,MasterSummary!$A10,TeakCosting!$B:$B,MasterSummary!G$1) -> 15438.1 | H10: =SUMIFS(TeakCosting!$F:$F,TeakCosting!$A:$A,MasterSummary!$A10,TeakCosting!$B:$B,MasterSummary!H$1) -> 6000 | I10: =SUMIFS(TeakCosting!$F:$F,TeakCosting!$A:$A,MasterSummary!$A10,TeakCosting!$B:$B,MasterSummary!I$1) -> 6480 | J10: =SUMIFS(TeakCosting!$F:$F,TeakCosting!$A:$A,MasterSummary!$A10,TeakCosting!$B:$B,MasterSummary!J$1) -> 3500 | K10: =SUMIFS(TeakCosting!$F:$F,TeakCosting!$A:$A,MasterSummary!$A10,TeakCosting!$B:$B,MasterSummary!K$1) -> 2400 | L10: =SUMIFS(TeakCosting!$F:$F,TeakCosting!$A:$A,MasterSummary!$A10,TeakCosting!$B:$B,MasterSummary!L$1) -> 1000 | M10: 0 | N10: 0.1 | O10: =SUM(G10:M10)*N10 -> 3481.81 | P10: =SUM(G10:M10)+O10 -> 38299.91 | Q10: =P10*F10 -> 38299.91 | R10: 0.3 | S10: =P10*R10 -> 11489.973 | T10: =S10*F10 -> 11489.973 | U10: =ROUND(P10+S10,-3) -> 50000 | V10: =F10*U10 -> 50000
A11: Bench 20 B1 | B11: 158 | C11: 64 | D11: 70 | E11: 45 | F11: 1 | G11: =SUMIFS(TeakCosting!$F:$F,TeakCosting!$A:$A,MasterSummary!$A11,TeakCosting!$B:$B,MasterSummary!G$1) -> 7865.8 | H11: =SUMIFS(TeakCosting!$F:$F,TeakCosting!$A:$A,MasterSummary!$A11,TeakCosting!$B:$B,MasterSummary!H$1) -> 4500 | I11: =SUMIFS(TeakCosting!$F:$F,TeakCosting!$A:$A,MasterSummary!$A11,TeakCosting!$B:$B,MasterSummary!I$1) -> 3200 | J11: =SUMIFS(TeakCosting!$F:$F,TeakCosting!$A:$A,MasterSummary!$A11,TeakCosting!$B:$B,MasterSummary!J$1) -> 7000 | K11: =SUMIFS(TeakCosting!$F:$F,TeakCosting!$A:$A,MasterSummary!$A11,TeakCosting!$B:$B,MasterSummary!K$1) -> 3009.375 | L11: =SUMIFS(TeakCosting!$F:$F,TeakCosting!$A:$A,MasterSummary!$A11,TeakCosting!$B:$B,MasterSummary!L$1) -> 1000 | M11: 0 | N11: 0.1 | O11: =SUM(G11:M11)*N11 -> 2657.5175 | P11: =SUM(G11:M11)+O11 -> 29232.692 | Q11: =P11*F11 -> 29232.692 | R11: 0.3 | S11: =P11*R11 -> 8769.8077 | T11: =S11*F11 -> 8769.8077 | U11: =ROUND(P11+S11,-3) -> 38000 | V11: =F11*U11 -> 38000
A12: Centre Table 02 A1 | B12: 76 | C12: 76 | D12: 36 | F12: 1 | G12: =SUMIFS(TeakCosting!$F:$F,TeakCosting!$A:$A,MasterSummary!$A12,TeakCosting!$B:$B,MasterSummary!G$1) -> 8100.6 | H12: =SUMIFS(TeakCosting!$F:$F,TeakCosting!$A:$A,MasterSummary!$A12,TeakCosting!$B:$B,MasterSummary!H$1) -> 2500 | I12: =SUMIFS(TeakCosting!$F:$F,TeakCosting!$A:$A,MasterSummary!$A12,TeakCosting!$B:$B,MasterSummary!I$1) -> 3680 | J12: =SUMIFS(TeakCosting!$F:$F,TeakCosting!$A:$A,MasterSummary!$A12,TeakCosting!$B:$B,MasterSummary!J$1) -> 0 | K12: =SUMIFS(TeakCosting!$F:$F,TeakCosting!$A:$A,MasterSummary!$A12,TeakCosting!$B:$B,MasterSummary!K$1) -> 0 | L12: =SUMIFS(TeakCosting!$F:$F,TeakCosting!$A:$A,MasterSummary!$A12,TeakCosting!$B:$B,MasterSummary!L$1) -> 1000 | M12: 0 | N12: 0.1 | O12: =SUM(G12:M12)*N12 -> 1528.06 | P12: =SUM(G12:M12)+O12 -> 16808.66 | Q12: =P12*F12 -> 16808.66 | R12: 0.3 | S12: =P12*R12 -> 5042.598 | T12: =S12*F12 -> 5042.598 | U12: =ROUND(P12+S12,-3) -> 22000 | V12: =F12*U12 -> 22000
A13: Centre Table 13 A1 | B13: 129 | C13: 76 | D13: 40 | F13: 1 | G13: =SUMIFS(TeakCosting!$F:$F,TeakCosting!$A:$A,MasterSummary!$A13,TeakCosting!$B:$B,MasterSummary!G$1) -> 10155.1 | H13: =SUMIFS(TeakCosting!$F:$F,TeakCosting!$A:$A,MasterSummary!$A13,TeakCosting!$B:$B,MasterSummary!H$1) -> 5000 | I13: =SUMIFS(TeakCosting!$F:$F,TeakCosting!$A:$A,MasterSummary!$A13,TeakCosting!$B:$B,MasterSummary!I$1) -> 5120 | J13: =SUMIFS(TeakCosting!$F:$F,TeakCosting!$A:$A,MasterSummary!$A13,TeakCosting!$B:$B,MasterSummary!J$1) -> 0 | K13: =SUMIFS(TeakCosting!$F:$F,TeakCosting!$A:$A,MasterSummary!$A13,TeakCosting!$B:$B,MasterSummary!K$1) -> 985 | L13: =SUMIFS(TeakCosting!$F:$F,TeakCosting!$A:$A,MasterSummary!$A13,TeakCosting!$B:$B,MasterSummary!L$1) -> 1000 | M13: 0 | N13: 0.1 | O13: =SUM(G13:M13)*N13 -> 2226.01 | P13: =SUM(G13:M13)+O13 -> 24486.11 | Q13: =P13*F13 -> 24486.11 | R13: 0.3 | S13: =P13*R13 -> 7345.833 | T13: =S13*F13 -> 7345.833 | U13: =ROUND(P13+S13,-3) -> 32000 | V13: =F13*U13 -> 32000
A14: Centre Table 23 A1 | B14: 102 | C14: 68 | D14: 45 | F14: 1 | G14: =SUMIFS(TeakCosting!$F:$F,TeakCosting!$A:$A,MasterSummary!$A14,TeakCosting!$B:$B,MasterSummary!G$1) -> 11857.4 | H14: =SUMIFS(TeakCosting!$F:$F,TeakCosting!$A:$A,MasterSummary!$A14,TeakCosting!$B:$B,MasterSummary!H$1) -> 3900 | I14: =SUMIFS(TeakCosting!$F:$F,TeakCosting!$A:$A,MasterSummary!$A14,TeakCosting!$B:$B,MasterSummary!I$1) -> 3680 | J14: =SUMIFS(TeakCosting!$F:$F,TeakCosting!$A:$A,MasterSummary!$A14,TeakCosting!$B:$B,MasterSummary!J$1) -> 0 | K14: =SUMIFS(TeakCosting!$F:$F,TeakCosting!$A:$A,MasterSummary!$A14,TeakCosting!$B:$B,MasterSummary!K$1) -> 0 | L14: =SUMIFS(TeakCosting!$F:$F,TeakCosting!$A:$A,MasterSummary!$A14,TeakCosting!$B:$B,MasterSummary!L$1) -> 1000 | M14: 0 | N14: 0.1 | O14: =SUM(G14:M14)*N14 -> 2043.74 | P14: =SUM(G14:M14)+O14 -> 22481.14 | Q14: =P14*F14 -> 22481.14 | R14: 0.3 | S14: =P14*R14 -> 6744.342 | T14: =S14*F14 -> 6744.342 | U14: =ROUND(P14+S14,-3) -> 29000 | V14: =F14*U14 -> 29000
A15: Chair 06 A1 | B15: 65 | C15: 83 | D15: 91 | E15: 39 | F15: 1 | G15: =SUMIFS(TeakCosting!$F:$F,TeakCosting!$A:$A,MasterSummary!$A15,TeakCosting!$B:$B,MasterSummary!G$1) -> 5928.7 | H15: =SUMIFS(TeakCosting!$F:$F,TeakCosting!$A:$A,MasterSummary!$A15,TeakCosting!$B:$B,MasterSummary!H$1) -> 3500 | I15: =SUMIFS(TeakCosting!$F:$F,TeakCosting!$A:$A,MasterSummary!$A15,TeakCosting!$B:$B,MasterSummary!I$1) -> 2000 | J15: =SUMIFS(TeakCosting!$F:$F,TeakCosting!$A:$A,MasterSummary!$A15,TeakCosting!$B:$B,MasterSummary!J$1) -> 9000 | K15: =SUMIFS(TeakCosting!$F:$F,TeakCosting!$A:$A,MasterSummary!$A15,TeakCosting!$B:$B,MasterSummary!K$1) -> 3650 | L15: =SUMIFS(TeakCosting!$F:$F,TeakCosting!$A:$A,MasterSummary!$A15,TeakCosting!$B:$B,MasterSummary!L$1) -> 1000 | M15: 0 | N15: 0.1 | O15: =SUM(G15:M15)*N15 -> 2507.87 | P15: =SUM(G15:M15)+O15 -> 27586.57 | Q15: =P15*F15 -> 27586.57 | R15: 0.3 | S15: =P15*R15 -> 8275.971 | T15: =S15*F15 -> 8275.971 | U15: =ROUND(P15+S15,-3) -> 36000 | V15: =F15*U15 -> 36000
A16: Chair 07 A1 | B16: 65 | C16: 83 | D16: 91 | E16: 39 | F16: 1 | G16: =SUMIFS(TeakCosting!$F:$F,TeakCosting!$A:$A,MasterSummary!$A16,TeakCosting!$B:$B,MasterSummary!G$1) -> 8570.2 | H16: =SUMIFS(TeakCosting!$F:$F,TeakCosting!$A:$A,MasterSummary!$A16,TeakCosting!$B:$B,MasterSummary!H$1) -> 7800 | I16: =SUMIFS(TeakCosting!$F:$F,TeakCosting!$A:$A,MasterSummary!$A16,TeakCosting!$B:$B,MasterSummary!I$1) -> 2720 | J16: =SUMIFS(TeakCosting!$F:$F,TeakCosting!$A:$A,MasterSummary!$A16,TeakCosting!$B:$B,MasterSummary!J$1) -> 1000 | K16: =SUMIFS(TeakCosting!$F:$F,TeakCosting!$A:$A,MasterSummary!$A16,TeakCosting!$B:$B,MasterSummary!K$1) -> 600 | L16: =SUMIFS(TeakCosting!$F:$F,TeakCosting!$A:$A,MasterSummary!$A16,TeakCosting!$B:$B,MasterSummary!L$1) -> 1000 | M16: 0 | N16: 0.1 | O16: =SUM(G16:M16)*N16 -> 2169.02 | P16: =SUM(G16:M16)+O16 -> 23859.22 | Q16: =P16*F16 -> 23859.22 | R16: 0.3 | S16: =P16*R16 -> 7157.766 | T16: =S16*F16 -> 7157.766 | U16: =ROUND(P16+S16,-3) -> 31000 | V16: =F16*U16 -> 31000
A17: Chair 12 C1 | B17: 54 | C17: 61 | D17: 89 | E17: 45 | F17: 1 | G17: =SUMIFS(TeakCosting!$F:$F,TeakCosting!$A:$A,MasterSummary!$A17,TeakCosting!$B:$B,MasterSummary!G$1) -> 3932.9 | H17: =SUMIFS(TeakCosting!$F:$F,TeakCosting!$A:$A,MasterSummary!$A17,TeakCosting!$B:$B,MasterSummary!H$1) -> 2000 | I17: =SUMIFS(TeakCosting!$F:$F,TeakCosting!$A:$A,MasterSummary!$A17,TeakCosting!$B:$B,MasterSummary!I$1) -> 1440 | J17: =SUMIFS(TeakCosting!$F:$F,TeakCosting!$A:$A,MasterSummary!$A17,TeakCosting!$B:$B,MasterSummary!J$1) -> 8000 | K17: =SUMIFS(TeakCosting!$F:$F,TeakCosting!$A:$A,MasterSummary!$A17,TeakCosting!$B:$B,MasterSummary!K$1) -> 2400 | L17: =SUMIFS(TeakCosting!$F:$F,TeakCosting!$A:$A,MasterSummary!$A17,TeakCosting!$B:$B,MasterSummary!L$1) -> 1000 | M17: 0 | N17: 0.1 | O17: =SUM(G17:M17)*N17 -> 1877.29 | P17: =SUM(G17:M17)+O17 -> 20650.19 | Q17: =P17*F17 -> 20650.19 | R17: 0.3 | S17: =P17*R17 -> 6195.057 | T17: =S17*F17 -> 6195.057 | U17: =ROUND(P17+S17,-3) -> 27000 | V17: =F17*U17 -> 27000
A18: Chair 42 A1 | B18: 62 | C18: 76 | D18: 82 | E18: 41 | F18: 1 | G18: =SUMIFS(TeakCosting!$F:$F,TeakCosting!$A:$A,MasterSummary!$A18,TeakCosting!$B:$B,MasterSummary!G$1) -> 9685.5 | H18: =SUMIFS(TeakCosting!$F:$F,TeakCosting!$A:$A,MasterSummary!$A18,TeakCosting!$B:$B,MasterSummary!H$1) -> 4500 | I18: =SUMIFS(TeakCosting!$F:$F,TeakCosting!$A:$A,MasterSummary!$A18,TeakCosting!$B:$B,MasterSummary!I$1) -> 2720 | J18: =SUMIFS(TeakCosting!$F:$F,TeakCosting!$A:$A,MasterSummary!$A18,TeakCosting!$B:$B,MasterSummary!J$1) -> 6000 | K18: =SUMIFS(TeakCosting!$F:$F,TeakCosting!$A:$A,MasterSummary!$A18,TeakCosting!$B:$B,MasterSummary!K$1) -> 2968.75 | L18: =SUMIFS(TeakCosting!$F:$F,TeakCosting!$A:$A,MasterSummary!$A18,TeakCosting!$B:$B,MasterSummary!L$1) -> 1000 | M18: 0 | N18: 0.1 | O18: =SUM(G18:M18)*N18 -> 2687.425 | P18: =SUM(G18:M18)+O18 -> 29561.675 | Q18: =P18*F18 -> 29561.675 | R18: 0.3 | S18: =P18*R18 -> 8868.5025 | T18: =S18*F18 -> 8868.5025 | U18: =ROUND(P18+S18,-3) -> 38000 | V18: =F18*U18 -> 38000
A19: Chair 27 A1 | B19: 67 | C19: 77 | D19: 70 | E19: 37 | F19: 1 | G19: =SUMIFS(TeakCosting!$F:$F,TeakCosting!$A:$A,MasterSummary!$A19,TeakCosting!$B:$B,MasterSummary!G$1) -> 9098.5 | H19: =SUMIFS(TeakCosting!$F:$F,TeakCosting!$A:$A,MasterSummary!$A19,TeakCosting!$B:$B,MasterSummary!H$1) -> 4000 | I19: =SUMIFS(TeakCosting!$F:$F,TeakCosting!$A:$A,MasterSummary!$A19,TeakCosting!$B:$B,MasterSummary!I$1) -> 3840 | J19: =SUMIFS(TeakCosting!$F:$F,TeakCosting!$A:$A,MasterSummary!$A19,TeakCosting!$B:$B,MasterSummary!J$1) -> 0 | K19: =SUMIFS(TeakCosting!$F:$F,TeakCosting!$A:$A,MasterSummary!$A19,TeakCosting!$B:$B,MasterSummary!K$1) -> 0 | L19: =SUMIFS(TeakCosting!$F:$F,TeakCosting!$A:$A,MasterSummary!$A19,TeakCosting!$B:$B,MasterSummary!L$1) -> 1000 | M19: 0 | N19: 0.1 | O19: =SUM(G19:M19)*N19 -> 1793.85 | P19: =SUM(G19:M19)+O19 -> 19732.35 | Q19: =P19*F19 -> 19732.35 | R19: 0.3 | S19: =P19*R19 -> 5919.705 | T19: =S19*F19 -> 5919.705 | U19: =ROUND(P19+S19,-3) -> 26000 | V19: =F19*U19 -> 26000
A20: Chair 44 C1 | B20: 45 | C20: 52 | D20: 79 | E20: 45 | F20: 1 | G20: =SUMIFS(TeakCosting!$F:$F,TeakCosting!$A:$A,MasterSummary!$A20,TeakCosting!$B:$B,MasterSummary!G$1) -> 3580.7 | H20: =SUMIFS(TeakCosting!$F:$F,TeakCosting!$A:$A,MasterSummary!$A20,TeakCosting!$B:$B,MasterSummary!H$1) -> 3450 | I20: =SUMIFS(TeakCosting!$F:$F,TeakCosting!$A:$A,MasterSummary!$A20,TeakCosting!$B:$B,MasterSummary!I$1) -> 880 | J20: =SUMIFS(TeakCosting!$F:$F,TeakCosting!$A:$A,MasterSummary!$A20,TeakCosting!$B:$B,MasterSummary!J$1) -> 4000 | K20: =SUMIFS(TeakCosting!$F:$F,TeakCosting!$A:$A,MasterSummary!$A20,TeakCosting!$B:$B,MasterSummary!K$1) -> 1200 | L20: =SUMIFS(TeakCosting!$F:$F,TeakCosting!$A:$A,MasterSummary!$A20,TeakCosting!$B:$B,MasterSummary!L$1) -> 1000 | M20: 0 | N20: 0.1 | O20: =SUM(G20:M20)*N20 -> 1411.07 | P20: =SUM(G20:M20)+O20 -> 15521.77 | Q20: =P20*F20 -> 15521.77 | R20: 0.3 | S20: =P20*R20 -> 4656.531 | T20: =S20*F20 -> 4656.531 | U20: =ROUND(P20+S20,-3) -> 20000 | V20: =F20*U20 -> 20000
A21: Chair 05 A1 | B21: 44 | C21: 51 | D21: 87 | E21: 45 | F21: 1 | G21: =SUMIFS(TeakCosting!$F:$F,TeakCosting!$A:$A,MasterSummary!$A21,TeakCosting!$B:$B,MasterSummary!G$1) -> 3111.1 | H21: =SUMIFS(TeakCosting!$F:$F,TeakCosting!$A:$A,MasterSummary!$A21,TeakCosting!$B:$B,MasterSummary!H$1) -> 4500 | I21: =SUMIFS(TeakCosting!$F:$F,TeakCosting!$A:$A,MasterSummary!$A21,TeakCosting!$B:$B,MasterSummary!I$1) -> 1040 | J21: =SUMIFS(TeakCosting!$F:$F,TeakCosting!$A:$A,MasterSummary!$A21,TeakCosting!$B:$B,MasterSummary!J$1) -> 1500 | K21: =SUMIFS(TeakCosting!$F:$F,TeakCosting!$A:$A,MasterSummary!$A21,TeakCosting!$B:$B,MasterSummary!K$1) -> 803.125 | L21: =SUMIFS(TeakCosting!$F:$F,TeakCosting!$A:$A,MasterSummary!$A21,TeakCosting!$B:$B,MasterSummary!L$1) -> 1000 | M21: 0 | N21: 0.1 | O21: =SUM(G21:M21)*N21 -> 1195.4225 | P21: =SUM(G21:M21)+O21 -> 13149.648 | Q21: =P21*F21 -> 13149.648 | R21: 0.3 | S21: =P21*R21 -> 3944.8943 | T21: =S21*F21 -> 3944.8943 | U21: =ROUND(P21+S21,-3) -> 17000 | V21: =F21*U21 -> 17000
A22: Chair 09 A1 | B22: 50 | C22: 50 | D22: 77 | E22: 45 | F22: 1 | G22: =SUMIFS(TeakCosting!$F:$F,TeakCosting!$A:$A,MasterSummary!$A22,TeakCosting!$B:$B,MasterSummary!G$1) -> 6398.3 | H22: =SUMIFS(TeakCosting!$F:$F,TeakCosting!$A:$A,MasterSummary!$A22,TeakCosting!$B:$B,MasterSummary!H$1) -> 5300 | I22: =SUMIFS(TeakCosting!$F:$F,TeakCosting!$A:$A,MasterSummary!$A22,TeakCosting!$B:$B,MasterSummary!I$1) -> 1920 | J22: =SUMIFS(TeakCosting!$F:$F,TeakCosting!$A:$A,MasterSummary!$A22,TeakCosting!$B:$B,MasterSummary!J$1) -> 0 | K22: =SUMIFS(TeakCosting!$F:$F,TeakCosting!$A:$A,MasterSummary!$A22,TeakCosting!$B:$B,MasterSummary!K$1) -> 0 | L22: =SUMIFS(TeakCosting!$F:$F,TeakCosting!$A:$A,MasterSummary!$A22,TeakCosting!$B:$B,MasterSummary!L$1) -> 1000 | M22: 0 | N22: 0.1 | O22: =SUM(G22:M22)*N22 -> 1461.83 | P22: =SUM(G22:M22)+O22 -> 16080.13 | Q22: =P22*F22 -> 16080.13 | R22: 0.3 | S22: =P22*R22 -> 4824.039 | T22: =S22*F22 -> 4824.039 | U22: =ROUND(P22+S22,-3) -> 21000 | V22: =F22*U22 -> 21000
A23: Dining Table 03 A1 | B23: 198 | C23: 92 | D23: 75 | F23: 1 | G23: =SUMIFS(TeakCosting!$F:$F,TeakCosting!$A:$A,MasterSummary!$A23,TeakCosting!$B:$B,MasterSummary!G$1) -> 30230.5 | H23: =SUMIFS(TeakCosting!$F:$F,TeakCosting!$A:$A,MasterSummary!$A23,TeakCosting!$B:$B,MasterSummary!H$1) -> 7000 | I23: =SUMIFS(TeakCosting!$F:$F,TeakCosting!$A:$A,MasterSummary!$A23,TeakCosting!$B:$B,MasterSummary!I$1) -> 13280 | J23: =SUMIFS(TeakCosting!$F:$F,TeakCosting!$A:$A,MasterSummary!$A23,TeakCosting!$B:$B,MasterSummary!J$1) -> 0 | K23: =SUMIFS(TeakCosting!$F:$F,TeakCosting!$A:$A,MasterSummary!$A23,TeakCosting!$B:$B,MasterSummary!K$1) -> 3047.92 | L23: =SUMIFS(TeakCosting!$F:$F,TeakCosting!$A:$A,MasterSummary!$A23,TeakCosting!$B:$B,MasterSummary!L$1) -> 1000 | M23: 0 | N23: 0.1 | O23: =SUM(G23:M23)*N23 -> 5455.842 | P23: =SUM(G23:M23)+O23 -> 60014.262 | Q23: =P23*F23 -> 60014.262 | R23: 0.3 | S23: =P23*R23 -> 18004.279 | T23: =S23*F23 -> 18004.279 | U23: =ROUND(P23+S23,-3) -> 78000 | V23: =F23*U23 -> 78000
A24: Side Table 01 A1 | B24: 48 | C24: 48 | D24: 49 | F24: 1 | G24: =SUMIFS(TeakCosting!$F:$F,TeakCosting!$A:$A,MasterSummary!$A24,TeakCosting!$B:$B,MasterSummary!G$1) -> 6574.4 | H24: =SUMIFS(TeakCosting!$F:$F,TeakCosting!$A:$A,MasterSummary!$A24,TeakCosting!$B:$B,MasterSummary!H$1) -> 3500 | I24: =SUMIFS(TeakCosting!$F:$F,TeakCosting!$A:$A,MasterSummary!$A24,TeakCosting!$B:$B,MasterSummary!I$1) -> 3120 | J24: =SUMIFS(TeakCosting!$F:$F,TeakCosting!$A:$A,MasterSummary!$A24,TeakCosting!$B:$B,MasterSummary!J$1) -> 0 | K24: =SUMIFS(TeakCosting!$F:$F,TeakCosting!$A:$A,MasterSummary!$A24,TeakCosting!$B:$B,MasterSummary!K$1) -> 761.98 | L24: =SUMIFS(TeakCosting!$F:$F,TeakCosting!$A:$A,MasterSummary!$A24,TeakCosting!$B:$B,MasterSummary!L$1) -> 1000 | M24: 0 | N24: 0.1 | O24: =SUM(G24:M24)*N24 -> 1495.638 | P24: =SUM(G24:M24)+O24 -> 16452.018 | Q24: =P24*F24 -> 16452.018 | R24: 0.3 | S24: =P24*R24 -> 4935.6054 | T24: =S24*F24 -> 4935.6054 | U24: =ROUND(P24+S24,-3) -> 21000 | V24: =F24*U24 -> 21000
A25: Side Table 02 A1 | B25: 40 | C25: 40 | D25: 53 | F25: 1 | G25: =SUMIFS(TeakCosting!$F:$F,TeakCosting!$A:$A,MasterSummary!$A25,TeakCosting!$B:$B,MasterSummary!G$1) -> 2788.25 | H25: =SUMIFS(TeakCosting!$F:$F,TeakCosting!$A:$A,MasterSummary!$A25,TeakCosting!$B:$B,MasterSummary!H$1) -> 2800 | I25: =SUMIFS(TeakCosting!$F:$F,TeakCosting!$A:$A,MasterSummary!$A25,TeakCosting!$B:$B,MasterSummary!I$1) -> 960 | J25: =SUMIFS(TeakCosting!$F:$F,TeakCosting!$A:$A,MasterSummary!$A25,TeakCosting!$B:$B,MasterSummary!J$1) -> 0 | K25: =SUMIFS(TeakCosting!$F:$F,TeakCosting!$A:$A,MasterSummary!$A25,TeakCosting!$B:$B,MasterSummary!K$1) -> 0 | L25: =SUMIFS(TeakCosting!$F:$F,TeakCosting!$A:$A,MasterSummary!$A25,TeakCosting!$B:$B,MasterSummary!L$1) -> 1000 | M25: 0 | N25: 0.1 | O25: =SUM(G25:M25)*N25 -> 754.825 | P25: =SUM(G25:M25)+O25 -> 8303.075 | Q25: =P25*F25 -> 8303.075 | R25: 0.3 | S25: =P25*R25 -> 2490.9225 | T25: =S25*F25 -> 2490.9225 | U25: =ROUND(P25+S25,-3) -> 11000 | V25: =F25*U25 -> 11000
A26: Side Table 02 C1 | B26: 45 | C26: 45 | D26: 53 | F26: 1 | G26: =SUMIFS(TeakCosting!$F:$F,TeakCosting!$A:$A,MasterSummary!$A26,TeakCosting!$B:$B,MasterSummary!G$1) -> 3463.3 | H26: =SUMIFS(TeakCosting!$F:$F,TeakCosting!$A:$A,MasterSummary!$A26,TeakCosting!$B:$B,MasterSummary!H$1) -> 3050 | I26: =SUMIFS(TeakCosting!$F:$F,TeakCosting!$A:$A,MasterSummary!$A26,TeakCosting!$B:$B,MasterSummary!I$1) -> 1120 | J26: =SUMIFS(TeakCosting!$F:$F,TeakCosting!$A:$A,MasterSummary!$A26,TeakCosting!$B:$B,MasterSummary!J$1) -> 0 | K26: =SUMIFS(TeakCosting!$F:$F,TeakCosting!$A:$A,MasterSummary!$A26,TeakCosting!$B:$B,MasterSummary!K$1) -> 0 | L26: =SUMIFS(TeakCosting!$F:$F,TeakCosting!$A:$A,MasterSummary!$A26,TeakCosting!$B:$B,MasterSummary!L$1) -> 1000 | M26: 0 | N26: 0.1 | O26: =SUM(G26:M26)*N26 -> 863.33 | P26: =SUM(G26:M26)+O26 -> 9496.63 | Q26: =P26*F26 -> 9496.63 | R26: 0.3 | S26: =P26*R26 -> 2848.989 | T26: =S26*F26 -> 2848.989 | U26: =ROUND(P26+S26,-3) -> 12000 | V26: =F26*U26 -> 12000
A27: Side Table 08 B1 | B27: 56 | C27: 40 | D27: 45 | F27: 1 | G27: =SUMIFS(TeakCosting!$F:$F,TeakCosting!$A:$A,MasterSummary!$A27,TeakCosting!$B:$B,MasterSummary!G$1) -> 10566 | H27: =SUMIFS(TeakCosting!$F:$F,TeakCosting!$A:$A,MasterSummary!$A27,TeakCosting!$B:$B,MasterSummary!H$1) -> 5400 | I27: =SUMIFS(TeakCosting!$F:$F,TeakCosting!$A:$A,MasterSummary!$A27,TeakCosting!$B:$B,MasterSummary!I$1) -> 5120 | J27: =SUMIFS(TeakCosting!$F:$F,TeakCosting!$A:$A,MasterSummary!$A27,TeakCosting!$B:$B,MasterSummary!J$1) -> 0 | K27: =SUMIFS(TeakCosting!$F:$F,TeakCosting!$A:$A,MasterSummary!$A27,TeakCosting!$B:$B,MasterSummary!K$1) -> 1145.3125 | L27: =SUMIFS(TeakCosting!$F:$F,TeakCosting!$A:$A,MasterSummary!$A27,TeakCosting!$B:$B,MasterSummary!L$1) -> 1000 | M27: 0 | N27: 0.1 | O27: =SUM(G27:M27)*N27 -> 2323.1312 | P27: =SUM(G27:M27)+O27 -> 25554.444 | Q27: =P27*F27 -> 25554.444 | R27: 0.3 | S27: =P27*R27 -> 7666.3331 | T27: =S27*F27 -> 7666.3331 | U27: =ROUND(P27+S27,-3) -> 33000 | V27: =F27*U27 -> 33000
A28: Side Table 31 A1 | B28: 45 | C28: 45 | D28: 45 | F28: 1 | G28: =SUMIFS(TeakCosting!$F:$F,TeakCosting!$A:$A,MasterSummary!$A28,TeakCosting!$B:$B,MasterSummary!G$1) -> 2935 | H28: =SUMIFS(TeakCosting!$F:$F,TeakCosting!$A:$A,MasterSummary!$A28,TeakCosting!$B:$B,MasterSummary!H$1) -> 2000 | I28: =SUMIFS(TeakCosting!$F:$F,TeakCosting!$A:$A,MasterSummary!$A28,TeakCosting!$B:$B,MasterSummary!I$1) -> 960 | J28: =SUMIFS(TeakCosting!$F:$F,TeakCosting!$A:$A,MasterSummary!$A28,TeakCosting!$B:$B,MasterSummary!J$1) -> 0 | K28: =SUMIFS(TeakCosting!$F:$F,TeakCosting!$A:$A,MasterSummary!$A28,TeakCosting!$B:$B,MasterSummary!K$1) -> 0 | L28: =SUMIFS(TeakCosting!$F:$F,TeakCosting!$A:$A,MasterSummary!$A28,TeakCosting!$B:$B,MasterSummary!L$1) -> 1000 | M28: 0 | N28: 0.1 | O28: =SUM(G28:M28)*N28 -> 689.5 | P28: =SUM(G28:M28)+O28 -> 7584.5 | Q28: =P28*F28 -> 7584.5 | R28: 0.3 | S28: =P28*R28 -> 2275.35 | T28: =S28*F28 -> 2275.35 | U28: =ROUND(P28+S28,-3) -> 10000 | V28: =F28*U28 -> 10000
A29: Side Table 42 A1 | B29: 46 | C29: 41 | D29: 46 | F29: 1 | G29: =SUMIFS(TeakCosting!$F:$F,TeakCosting!$A:$A,MasterSummary!$A29,TeakCosting!$B:$B,MasterSummary!G$1) -> 9039.8 | H29: =SUMIFS(TeakCosting!$F:$F,TeakCosting!$A:$A,MasterSummary!$A29,TeakCosting!$B:$B,MasterSummary!H$1) -> 5225 | I29: =SUMIFS(TeakCosting!$F:$F,TeakCosting!$A:$A,MasterSummary!$A29,TeakCosting!$B:$B,MasterSummary!I$1) -> 4160 | J29: =SUMIFS(TeakCosting!$F:$F,TeakCosting!$A:$A,MasterSummary!$A29,TeakCosting!$B:$B,MasterSummary!J$1) -> 0 | K29: =SUMIFS(TeakCosting!$F:$F,TeakCosting!$A:$A,MasterSummary!$A29,TeakCosting!$B:$B,MasterSummary!K$1) -> 1669.2725 | L29: =SUMIFS(TeakCosting!$F:$F,TeakCosting!$A:$A,MasterSummary!$A29,TeakCosting!$B:$B,MasterSummary!L$1) -> 1000 | M29: 0 | N29: 0.1 | O29: =SUM(G29:M29)*N29 -> 2109.4072 | P29: =SUM(G29:M29)+O29 -> 23203.48 | Q29: =P29*F29 -> 23203.48 | R29: 0.3 | S29: =P29*R29 -> 6961.0439 | T29: =S29*F29 -> 6961.0439 | U29: =ROUND(P29+S29,-3) -> 30000 | V29: =F29*U29 -> 30000
A30: Sofa 23 B1 | B30: 170 | C30: 84 | D30: 79 | E30: 43 | F30: 1 | G30: =SUMIFS(TeakCosting!$F:$F,TeakCosting!$A:$A,MasterSummary!$A30,TeakCosting!$B:$B,MasterSummary!G$1) -> 17962.2 | H30: =SUMIFS(TeakCosting!$F:$F,TeakCosting!$A:$A,MasterSummary!$A30,TeakCosting!$B:$B,MasterSummary!H$1) -> 8000 | I30: =SUMIFS(TeakCosting!$F:$F,TeakCosting!$A:$A,MasterSummary!$A30,TeakCosting!$B:$B,MasterSummary!I$1) -> 5280 | J30: =SUMIFS(TeakCosting!$F:$F,TeakCosting!$A:$A,MasterSummary!$A30,TeakCosting!$B:$B,MasterSummary!J$1) -> 24000 | K30: =SUMIFS(TeakCosting!$F:$F,TeakCosting!$A:$A,MasterSummary!$A30,TeakCosting!$B:$B,MasterSummary!K$1) -> 5400 | L30: =SUMIFS(TeakCosting!$F:$F,TeakCosting!$A:$A,MasterSummary!$A30,TeakCosting!$B:$B,MasterSummary!L$1) -> 1000 | M30: 0 | N30: 0.1 | O30: =SUM(G30:M30)*N30 -> 6164.22 | P30: =SUM(G30:M30)+O30 -> 67806.42 | Q30: =P30*F30 -> 67806.42 | R30: 0.3 | S30: =P30*R30 -> 20341.926 | T30: =S30*F30 -> 20341.926 | U30: =ROUND(P30+S30,-3) -> 88000 | V30: =F30*U30 -> 88000
A31: Sofa 28 C1 | B31: 255 | C31: 75 | D31: 84 | E31: 40 | F31: 1 | G31: =SUMIFS(TeakCosting!$F:$F,TeakCosting!$A:$A,MasterSummary!$A31,TeakCosting!$B:$B,MasterSummary!G$1) -> 21542.9 | H31: =SUMIFS(TeakCosting!$F:$F,TeakCosting!$A:$A,MasterSummary!$A31,TeakCosting!$B:$B,MasterSummary!H$1) -> 4500 | I31: =SUMIFS(TeakCosting!$F:$F,TeakCosting!$A:$A,MasterSummary!$A31,TeakCosting!$B:$B,MasterSummary!I$1) -> 7520 | J31: =SUMIFS(TeakCosting!$F:$F,TeakCosting!$A:$A,MasterSummary!$A31,TeakCosting!$B:$B,MasterSummary!J$1) -> 32000 | K31: =SUMIFS(TeakCosting!$F:$F,TeakCosting!$A:$A,MasterSummary!$A31,TeakCosting!$B:$B,MasterSummary!K$1) -> 10200 | L31: =SUMIFS(TeakCosting!$F:$F,TeakCosting!$A:$A,MasterSummary!$A31,TeakCosting!$B:$B,MasterSummary!L$1) -> 1000 | M31: 0 | N31: 0.1 | O31: =SUM(G31:M31)*N31 -> 7676.29 | P31: =SUM(G31:M31)+O31 -> 84439.19 | Q31: =P31*F31 -> 84439.19 | R31: 0.3 | S31: =P31*R31 -> 25331.757 | T31: =S31*F31 -> 25331.757 | U31: =ROUND(P31+S31,-3) -> 110000 | V31: =F31*U31 -> 110000
A32: Sofa 36 A1 | B32: 268 | C32: 80 | D32: 80 | E32: 35 | F32: 1 | G32: =SUMIFS(TeakCosting!$F:$F,TeakCosting!$A:$A,MasterSummary!$A32,TeakCosting!$B:$B,MasterSummary!G$1) -> 22599.5 | H32: =SUMIFS(TeakCosting!$F:$F,TeakCosting!$A:$A,MasterSummary!$A32,TeakCosting!$B:$B,MasterSummary!H$1) -> 5500 | I32: =SUMIFS(TeakCosting!$F:$F,TeakCosting!$A:$A,MasterSummary!$A32,TeakCosting!$B:$B,MasterSummary!I$1) -> 8160 | J32: =SUMIFS(TeakCosting!$F:$F,TeakCosting!$A:$A,MasterSummary!$A32,TeakCosting!$B:$B,MasterSummary!J$1) -> 27000 | K32: =SUMIFS(TeakCosting!$F:$F,TeakCosting!$A:$A,MasterSummary!$A32,TeakCosting!$B:$B,MasterSummary!K$1) -> 9600 | L32: =SUMIFS(TeakCosting!$F:$F,TeakCosting!$A:$A,MasterSummary!$A32,TeakCosting!$B:$B,MasterSummary!L$1) -> 1000 | M32: 0 | N32: 0.1 | O32: =SUM(G32:M32)*N32 -> 7385.95 | P32: =SUM(G32:M32)+O32 -> 81245.45 | Q32: =P32*F32 -> 81245.45 | R32: 0.3 | S32: =P32*R32 -> 24373.635 | T32: =S32*F32 -> 24373.635 | U32: =ROUND(P32+S32,-3) -> 106000 | V32: =F32*U32 -> 106000
A33: Storage 16 A1 | B33: 150 | C33: 42 | D33: 80 | F33: 1 | G33: =SUMIFS(TeakCosting!$F:$F,TeakCosting!$A:$A,MasterSummary!$A33,TeakCosting!$B:$B,MasterSummary!G$1) -> 31052.3 | H33: =SUMIFS(TeakCosting!$F:$F,TeakCosting!$A:$A,MasterSummary!$A33,TeakCosting!$B:$B,MasterSummary!H$1) -> 7950 | I33: =SUMIFS(TeakCosting!$F:$F,TeakCosting!$A:$A,MasterSummary!$A33,TeakCosting!$B:$B,MasterSummary!I$1) -> 16800 | J33: =SUMIFS(TeakCosting!$F:$F,TeakCosting!$A:$A,MasterSummary!$A33,TeakCosting!$B:$B,MasterSummary!J$1) -> 0 | K33: =SUMIFS(TeakCosting!$F:$F,TeakCosting!$A:$A,MasterSummary!$A33,TeakCosting!$B:$B,MasterSummary!K$1) -> 4919.795 | L33: =SUMIFS(TeakCosting!$F:$F,TeakCosting!$A:$A,MasterSummary!$A33,TeakCosting!$B:$B,MasterSummary!L$1) -> 1000 | M33: 0 | N33: 0.1 | O33: =SUM(G33:M33)*N33 -> 6172.2095 | P33: =SUM(G33:M33)+O33 -> 67894.304 | Q33: =P33*F33 -> 67894.304 | R33: 0.3 | S33: =P33*R33 -> 20368.291 | T33: =S33*F33 -> 20368.291 | U33: =ROUND(P33+S33,-3) -> 88000 | V33: =F33*U33 -> 88000
A34: Storage 29 C1 | B34: 129 | C34: 35 | D34: 80 | F34: 1 | G34: =SUMIFS(TeakCosting!$F:$F,TeakCosting!$A:$A,MasterSummary!$A34,TeakCosting!$B:$B,MasterSummary!G$1) -> 22599.5 | H34: =SUMIFS(TeakCosting!$F:$F,TeakCosting!$A:$A,MasterSummary!$A34,TeakCosting!$B:$B,MasterSummary!H$1) -> 5450 | I34: =SUMIFS(TeakCosting!$F:$F,TeakCosting!$A:$A,MasterSummary!$A34,TeakCosting!$B:$B,MasterSummary!I$1) -> 9840 | J34: =SUMIFS(TeakCosting!$F:$F,TeakCosting!$A:$A,MasterSummary!$A34,TeakCosting!$B:$B,MasterSummary!J$1) -> 0 | K34: =SUMIFS(TeakCosting!$F:$F,TeakCosting!$A:$A,MasterSummary!$A34,TeakCosting!$B:$B,MasterSummary!K$1) -> 1572.1875 | L34: =SUMIFS(TeakCosting!$F:$F,TeakCosting!$A:$A,MasterSummary!$A34,TeakCosting!$B:$B,MasterSummary!L$1) -> 1000 | M34: 0 | N34: 0.1 | O34: =SUM(G34:M34)*N34 -> 4046.1688 | P34: =SUM(G34:M34)+O34 -> 44507.856 | Q34: =P34*F34 -> 44507.856 | R34: 0.3 | S34: =P34*R34 -> 13352.357 | T34: =S34*F34 -> 13352.357 | U34: =ROUND(P34+S34,-3) -> 58000 | V34: =F34*U34 -> 58000
A35: Storage 34 A1 | B35: 146 | C35: 40 | D35: 92 | F35: 1 | G35: =SUMIFS(TeakCosting!$F:$F,TeakCosting!$A:$A,MasterSummary!$A35,TeakCosting!$B:$B,MasterSummary!G$1) -> 35924.4 | H35: =SUMIFS(TeakCosting!$F:$F,TeakCosting!$A:$A,MasterSummary!$A35,TeakCosting!$B:$B,MasterSummary!H$1) -> 7500 | I35: =SUMIFS(TeakCosting!$F:$F,TeakCosting!$A:$A,MasterSummary!$A35,TeakCosting!$B:$B,MasterSummary!I$1) -> 12640 | J35: =SUMIFS(TeakCosting!$F:$F,TeakCosting!$A:$A,MasterSummary!$A35,TeakCosting!$B:$B,MasterSummary!J$1) -> 0 | K35: =SUMIFS(TeakCosting!$F:$F,TeakCosting!$A:$A,MasterSummary!$A35,TeakCosting!$B:$B,MasterSummary!K$1) -> 4781.875 | L35: =SUMIFS(TeakCosting!$F:$F,TeakCosting!$A:$A,MasterSummary!$A35,TeakCosting!$B:$B,MasterSummary!L$1) -> 1000 | M35: 0 | N35: 0.1 | O35: =SUM(G35:M35)*N35 -> 6184.6275 | P35: =SUM(G35:M35)+O35 -> 68030.902 | Q35: =P35*F35 -> 68030.902 | R35: 0.3 | S35: =P35*R35 -> 20409.271 | T35: =S35*F35 -> 20409.271 | U35: =ROUND(P35+S35,-3) -> 88000 | V35: =F35*U35 -> 88000
A36: Study Table 02 A1 | B36: 130 | C36: 60 | D36: 75 | F36: 1 | G36: =SUMIFS(TeakCosting!$F:$F,TeakCosting!$A:$A,MasterSummary!$A36,TeakCosting!$B:$B,MasterSummary!G$1) -> 16670.8 | H36: =SUMIFS(TeakCosting!$F:$F,TeakCosting!$A:$A,MasterSummary!$A36,TeakCosting!$B:$B,MasterSummary!H$1) -> 4500 | I36: =SUMIFS(TeakCosting!$F:$F,TeakCosting!$A:$A,MasterSummary!$A36,TeakCosting!$B:$B,MasterSummary!I$1) -> 8480 | J36: =SUMIFS(TeakCosting!$F:$F,TeakCosting!$A:$A,MasterSummary!$A36,TeakCosting!$B:$B,MasterSummary!J$1) -> 0 | K36: =SUMIFS(TeakCosting!$F:$F,TeakCosting!$A:$A,MasterSummary!$A36,TeakCosting!$B:$B,MasterSummary!K$1) -> 2228.94 | L36: =SUMIFS(TeakCosting!$F:$F,TeakCosting!$A:$A,MasterSummary!$A36,TeakCosting!$B:$B,MasterSummary!L$1) -> 1000 | M36: 0 | N36: 0.1 | O36: =SUM(G36:M36)*N36 -> 3287.974 | P36: =SUM(G36:M36)+O36 -> 36167.714 | Q36: =P36*F36 -> 36167.714 | R36: 0.3 | S36: =P36*R36 -> 10850.314 | T36: =S36*F36 -> 10850.314 | U36: =ROUND(P36+S36,-3) -> 47000 | V36: =F36*U36 -> 47000
A37: Study Table 11 A1 | B37: 130 | C37: 60 | D37: 75 | F37: 1 | G37: =SUMIFS(TeakCosting!$F:$F,TeakCosting!$A:$A,MasterSummary!$A37,TeakCosting!$B:$B,MasterSummary!G$1) -> 21719 | H37: =SUMIFS(TeakCosting!$F:$F,TeakCosting!$A:$A,MasterSummary!$A37,TeakCosting!$B:$B,MasterSummary!H$1) -> 5000 | I37: =SUMIFS(TeakCosting!$F:$F,TeakCosting!$A:$A,MasterSummary!$A37,TeakCosting!$B:$B,MasterSummary!I$1) -> 8960 | J37: =SUMIFS(TeakCosting!$F:$F,TeakCosting!$A:$A,MasterSummary!$A37,TeakCosting!$B:$B,MasterSummary!J$1) -> 0 | K37: =SUMIFS(TeakCosting!$F:$F,TeakCosting!$A:$A,MasterSummary!$A37,TeakCosting!$B:$B,MasterSummary!K$1) -> 1657.88 | L37: =SUMIFS(TeakCosting!$F:$F,TeakCosting!$A:$A,MasterSummary!$A37,TeakCosting!$B:$B,MasterSummary!L$1) -> 1000 | M37: 0 | N37: 0.1 | O37: =SUM(G37:M37)*N37 -> 3833.688 | P37: =SUM(G37:M37)+O37 -> 42170.568 | Q37: =P37*F37 -> 42170.568 | R37: 0.3 | S37: =P37*R37 -> 12651.17 | T37: =S37*F37 -> 12651.17 | U37: =ROUND(P37+S37,-3) -> 55000 | V37: =F37*U37 -> 55000
A38: Swing 04 A1 | B38: 153 | C38: 61 | D38: 43 | F38: 1 | G38: =SUMIFS(TeakCosting!$F:$F,TeakCosting!$A:$A,MasterSummary!$A38,TeakCosting!$B:$B,MasterSummary!G$1) -> 14675 | H38: =SUMIFS(TeakCosting!$F:$F,TeakCosting!$A:$A,MasterSummary!$A38,TeakCosting!$B:$B,MasterSummary!H$1) -> 4500 | I38: =SUMIFS(TeakCosting!$F:$F,TeakCosting!$A:$A,MasterSummary!$A38,TeakCosting!$B:$B,MasterSummary!I$1) -> 5120 | J38: =SUMIFS(TeakCosting!$F:$F,TeakCosting!$A:$A,MasterSummary!$A38,TeakCosting!$B:$B,MasterSummary!J$1) -> 9500 | K38: =SUMIFS(TeakCosting!$F:$F,TeakCosting!$A:$A,MasterSummary!$A38,TeakCosting!$B:$B,MasterSummary!K$1) -> 20700 | L38: =SUMIFS(TeakCosting!$F:$F,TeakCosting!$A:$A,MasterSummary!$A38,TeakCosting!$B:$B,MasterSummary!L$1) -> 1000 | M38: 0 | N38: 0.1 | O38: =SUM(G38:M38)*N38 -> 5549.5 | P38: =SUM(G38:M38)+O38 -> 61044.5 | Q38: =P38*F38 -> 61044.5 | R38: 0.3 | S38: =P38*R38 -> 18313.35 | T38: =S38*F38 -> 18313.35 | U38: =ROUND(P38+S38,-3) -> 79000 | V38: =F38*U38 -> 79000
A39: TV Console 09 A1 | B39: 159 | C39: 45 | D39: 45 | F39: 1 | G39: =SUMIFS(TeakCosting!$F:$F,TeakCosting!$A:$A,MasterSummary!$A39,TeakCosting!$B:$B,MasterSummary!G$1) -> 24712.7 | H39: =SUMIFS(TeakCosting!$F:$F,TeakCosting!$A:$A,MasterSummary!$A39,TeakCosting!$B:$B,MasterSummary!H$1) -> 6300 | I39: =SUMIFS(TeakCosting!$F:$F,TeakCosting!$A:$A,MasterSummary!$A39,TeakCosting!$B:$B,MasterSummary!I$1) -> 13680 | J39: =SUMIFS(TeakCosting!$F:$F,TeakCosting!$A:$A,MasterSummary!$A39,TeakCosting!$B:$B,MasterSummary!J$1) -> 0 | K39: =SUMIFS(TeakCosting!$F:$F,TeakCosting!$A:$A,MasterSummary!$A39,TeakCosting!$B:$B,MasterSummary!K$1) -> 3174.32 | L39: =SUMIFS(TeakCosting!$F:$F,TeakCosting!$A:$A,MasterSummary!$A39,TeakCosting!$B:$B,MasterSummary!L$1) -> 1000 | M39: 0 | N39: 0.1 | O39: =SUM(G39:M39)*N39 -> 4886.702 | P39: =SUM(G39:M39)+O39 -> 53753.722 | Q39: =P39*F39 -> 53753.722 | R39: 0.3 | S39: =P39*R39 -> 16126.117 | T39: =S39*F39 -> 16126.117 | U39: =ROUND(P39+S39,-3) -> 70000 | V39: =F39*U39 -> 70000
A40: TV Console 29 A1 | B40: 112 | C40: 28 | D40: 50 | F40: 1 | G40: =SUMIFS(TeakCosting!$F:$F,TeakCosting!$A:$A,MasterSummary!$A40,TeakCosting!$B:$B,MasterSummary!G$1) -> 2348 | H40: =SUMIFS(TeakCosting!$F:$F,TeakCosting!$A:$A,MasterSummary!$A40,TeakCosting!$B:$B,MasterSummary!H$1) -> 6000 | I40: =SUMIFS(TeakCosting!$F:$F,TeakCosting!$A:$A,MasterSummary!$A40,TeakCosting!$B:$B,MasterSummary!I$1) -> 2240 | J40: =SUMIFS(TeakCosting!$F:$F,TeakCosting!$A:$A,MasterSummary!$A40,TeakCosting!$B:$B,MasterSummary!J$1) -> 0 | K40: =SUMIFS(TeakCosting!$F:$F,TeakCosting!$A:$A,MasterSummary!$A40,TeakCosting!$B:$B,MasterSummary!K$1) -> 5242.5 | L40: =SUMIFS(TeakCosting!$F:$F,TeakCosting!$A:$A,MasterSummary!$A40,TeakCosting!$B:$B,MasterSummary!L$1) -> 1000 | M40: 0 | N40: 0.1 | O40: =SUM(G40:M40)*N40 -> 1683.05 | P40: =SUM(G40:M40)+O40 -> 18513.55 | Q40: =P40*F40 -> 18513.55 | R40: 0.3 | S40: =P40*R40 -> 5554.065 | T40: =S40*F40 -> 5554.065 | U40: =ROUND(P40+S40,-3) -> 24000 | V40: =F40*U40 -> 24000
...

Sheet TeakCosting
A1: Furniture Code | B1: Expense Category | C1: Component | D1: Qty | E1: Rate | F1: Amount
A2: Barstool 01 B1 | B2: {=INDEX(Database!A:A, MATCH(C2, Database!B:B, 0))} -> Wood | C2: Teak wood | D2: 0.72 | E2: =VLOOKUP(C2,Database!$B$2:$C$219,2,FALSE) -> 5200 | F2: =D2*E2 -> 3744
A3: Barstool 01 B1 | B3: {=INDEX(Database!A:A, MATCH(C3, Database!B:B, 0))} -> Wood | C3: Carpentry Charges | D3: =SUM(D2) -> 0.72 | E3: =VLOOKUP(C3,Database!$B$2:$C$219,2,FALSE) -> 150 | F3: =D3*E3 -> 108
A4: Barstool 01 B1 | B4: {=INDEX(Database!A:A, MATCH(C4, Database!B:B, 0))} -> Wood | C4: Carpentry OH | D4: =SUM(F2) -> 3744 | E4: =VLOOKUP(C4,Database!$B$2:$C$219,2,FALSE) -> 0.1 | F4: =D4*E4 -> 374.4
A5: Barstool 01 B1 | B5: {=INDEX(Database!A:A, MATCH(C5, Database!B:B, 0))} -> Labour | C5: Labour | D5: 1 | E5: 3000 | F5: =D5*E5 -> 3000
A6: Barstool 01 B1 | B6: {=INDEX(Database!A:A, MATCH(C6, Database!B:B, 0))} -> Polish | C6: Water PU Polish - Spray | D6: 9 | E6: =VLOOKUP(C6,Database!$B$2:$C$219,2,FALSE) -> 160 | F6: =D6*E6 -> 1440
A7: Barstool 01 B1 | B7: {=INDEX(Database!A:A, MATCH(C7, Database!B:B, 0))} -> Material | C7: 12mm plywood - Mikasa or Green | D7: =2/32 -> 0.0625 | E7: =VLOOKUP(C7,Database!$B$2:$C$219,2,FALSE) -> 2600 | F7: =D7*E7 -> 162.5
A8: Barstool 01 B1 | B8: {=INDEX(Database!A:A, MATCH(C8, Database!B:B, 0))} -> Labour | C8: CNC work | D8: 1.5 | E8: =VLOOKUP(C8,Database!$B$2:$C$219,2,FALSE) -> 650 | F8: =D8*E8 -> 975
A9: Barstool 01 B1 | B9: {=INDEX(Database!A:A, MATCH(C9, Database!B:B, 0))} -> Material | C9: Fabric | D9: 0.5 | E9: =VLOOKUP(C9,Database!$B$2:$C$219,2,FALSE) -> 1200 | F9: =D9*E9 -> 600
A10: Barstool 01 B1 | B10: {=INDEX(Database!A:A, MATCH(C10, Database!B:B, 0))} -> Upholstery | C10: Upholstery | D10: 1 | E10: 2000 | F10: =D10*E10 -> 2000
A11: Barstool 01 B1 | B11: {=INDEX(Database!A:A, MATCH(C11, Database!B:B, 0))} -> Misc. | C11: Misc. | D11: 1 | E11: 1000 | F11: =D11*E11 -> 1000
A12: Barstool 01 B1 | C12: Total | F12: =SUM(F2:F11) -> 13403.9
A14: Barstool 03 A1 | B14: {=INDEX(Database!A:A, MATCH(C14, Database!B:B, 0))} -> Wood | C14: Teak wood | D14: 0.73 | E14: =VLOOKUP(C14,Database!$B$2:$C$219,2,FALSE) -> 5200 | F14: =D14*E14 -> 3796
A15: Barstool 03 A1 | B15: {=INDEX(Database!A:A, MATCH(C15, Database!B:B, 0))} -> Wood | C15: Carpentry Charges | D15: =SUM(D14) -> 0.73 | E15: =VLOOKUP(C15,Database!$B$2:$C$219,2,FALSE) -> 150 | F15: =D15*E15 -> 109.5
A16: Barstool 03 A1 | B16: {=INDEX(Database!A:A, MATCH(C16, Database!B:B, 0))} -> Wood | C16: Carpentry OH | D16: =SUM(F14) -> 3796 | E16: =VLOOKUP(C16,Database!$B$2:$C$219,2,FALSE) -> 0.1 | F16: =D16*E16 -> 379.6
A17: Barstool 03 A1 | B17: {=INDEX(Database!A:A, MATCH(C17, Database!B:B, 0))} -> Labour | C17: Labour | D17: 1 | E17: 3000 | F17: =D17*E17 -> 3000
A18: Barstool 03 A1 | B18: {=INDEX(Database!A:A, MATCH(C18, Database!B:B, 0))} -> Polish | C18: Water PU Polish - Spray | D18: 9 | E18: =VLOOKUP(C18,Database!$B$2:$C$219,2,FALSE) -> 160 | F18: =D18*E18 -> 1440
A19: Barstool 03 A1 | B19: {=INDEX(Database!A:A, MATCH(C19, Database!B:B, 0))} -> Material | C19: 12mm plywood - Mikasa or Green | D19: =2/32 -> 0.0625 | E19: =VLOOKUP(C19,Database!$B$2:$C$219,2,FALSE) -> 2600 | F19: =D19*E19 -> 162.5
A20: Barstool 03 A1 | B20: {=INDEX(Database!A:A, MATCH(C20, Database!B:B, 0))} -> Labour | C20: Lathe Work | D20: 2 | E20: =VLOOKUP(C20,Database!$B$2:$C$219,2,FALSE) -> 150 | F20: =D20*E20 -> 300
A21: Barstool 03 A1 | B21: {=INDEX(Database!A:A, MATCH(C21, Database!B:B, 0))} -> Labour | C21: CNC work | D21: 1.5 | E21: =VLOOKUP(C21,Database!$B$2:$C$219,2,FALSE) -> 650 | F21: =D21*E21 -> 975
A22: Barstool 03 A1 | B22: {=INDEX(Database!A:A, MATCH(C22, Database!B:B, 0))} -> Material | C22: Fabric | D22: 0.5 | E22: =VLOOKUP(C22,Database!$B$2:$C$219,2,FALSE) -> 1200 | F22: =D22*E22 -> 600
A23: Barstool 03 A1 | B23: {=INDEX(Database!A:A, MATCH(C23, Database!B:B, 0))} -> Upholstery | C23: Upholstery | D23: 1 | E23: 2000 | F23: =D23*E23 -> 2000
A24: Barstool 03 A1 | B24: {=INDEX(Database!A:A, MATCH(C24, Database!B:B, 0))} -> Misc. | C24: Misc. | D24: 1 | E24: 1000 | F24: =D24*E24 -> 1000
A25: Barstool 03 A1 | C25: Total | F25: =SUM(F14:F24) -> 13762.6
A27: Barstool 11 A1 | B27: {=INDEX(Database!A:A, MATCH(C27, Database!B:B, 0))} -> Wood | C27: Teak wood | D27: 1.32 | E27: =VLOOKUP(C27,Database!$B$2:$C$219,2,FALSE) -> 5200 | F27: =D27*E27 -> 6864
A28: Barstool 11 A1 | B28: {=INDEX(Database!A:A, MATCH(C28, Database!B:B, 0))} -> Wood | C28: Carpentry Charges | D28: =SUM(D27) -> 1.32 | E28: =VLOOKUP(C28,Database!$B$2:$C$219,2,FALSE) -> 150 | F28: =D28*E28 -> 198
A29: Barstool 11 A1 | B29: {=INDEX(Database!A:A, MATCH(C29, Database!B:B, 0))} -> Wood | C29: Carpentry OH | D29: =SUM(F27) -> 6864 | E29: =VLOOKUP(C29,Database!$B$2:$C$219,2,FALSE) -> 0.1 | F29: =D29*E29 -> 686.4
A30: Barstool 11 A1 | B30: {=INDEX(Database!A:A, MATCH(C30, Database!B:B, 0))} -> Labour | C30: Labour | D30: 1 | E30: 4000 | F30: =D30*E30 -> 4000
A31: Barstool 11 A1 | B31: {=INDEX(Database!A:A, MATCH(C31, Database!B:B, 0))} -> Polish | C31: Water PU Polish - Spray | D31: 9 | E31: =VLOOKUP(C31,Database!$B$2:$C$219,2,FALSE) -> 160 | F31: =D31*E31 -> 1440
A32: Barstool 11 A1 | B32: {=INDEX(Database!A:A, MATCH(C32, Database!B:B, 0))} -> Material | C32: 12mm plywood - Mikasa or Green | D32: =2/32 -> 0.0625 | E32: =VLOOKUP(C32,Database!$B$2:$C$219,2,FALSE) -> 2600 | F32: =D32*E32 -> 162.5
A33: Barstool 11 A1 | B33: {=INDEX(Database!A:A, MATCH(C33, Database!B:B, 0))} -> Labour | C33: Lathe Work | D33: 11.5 | E33: =VLOOKUP(C33,Database!$B$2:$C$219,2,FALSE) -> 150 | F33: =D33*E33 -> 1725
A34: Barstool 11 A1 | B34: {=INDEX(Database!A:A, MATCH(C34, Database!B:B, 0))} -> Labour | C34: CNC work | D34: 1.5 | E34: =VLOOKUP(C34,Database!$B$2:$C$219,2,FALSE) -> 650 | F34: =D34*E34 -> 975
A35: Barstool 11 A1 | B35: {=INDEX(Database!A:A, MATCH(C35, Database!B:B, 0))} -> Material | C35: Fabric | D35: 0.5 | E35: =VLOOKUP(C35,Database!$B$2:$C$219,2,FALSE) -> 1200 | F35: =D35*E35 -> 600
A36: Barstool 11 A1 | B36: {=INDEX(Database!A:A, MATCH(C36, Database!B:B, 0))} -> Upholstery | C36: Upholstery | D36: 1 | E36: 1500 | F36: =D36*E36 -> 1500
A37: Barstool 11 A1 | B37: {=INDEX(Database!A:A, MATCH(C37, Database!B:B, 0))} -> Misc. | C37: Misc. | D37: 1 | E37: 1000 | F37: =D37*E37 -> 1000
A38: Barstool 11 A1 | C38: Total | F38: =SUM(F27:F37) -> 19150.9
A40: Bed 01 A1 | B40: {=INDEX(Database!A:A, MATCH(C40, Database!B:B, 0))} -> Wood | C40: Teak wood | D40: 4.7 | E40: =VLOOKUP(C40,Database!$B$2:$C$219,2,FALSE) -> 5200 | F40: =D40*E40 -> 24440
A41: Bed 01 A1 | B41: {=INDEX(Database!A:A, MATCH(C41, Database!B:B, 0))} -> Wood | C41: Honne wood | D41: 0.93 | E41: =VLOOKUP(C41,Database!$B$2:$C$219,2,FALSE) -> 3000 | F41: =D41*E41 -> 2790
A42: Bed 01 A1 | B42: {=INDEX(Database!A:A, MATCH(C42, Database!B:B, 0))} -> Wood | C42: Pinewood | D42: 3.5 | E42: =VLOOKUP(C42,Database!$B$2:$C$219,2,FALSE) -> 1500 | F42: =D42*E42 -> 5250
A43: Bed 01 A1 | B43: {=INDEX(Database!A:A, MATCH(C43, Database!B:B, 0))} -> Wood | C43: Carpentry Charges | D43: =SUM(D40:D42) -> 9.13 | E43: =VLOOKUP(C43,Database!$B$2:$C$219,2,FALSE) -> 150 | F43: =D43*E43 -> 1369.5
...

Sheet Database
A1: Category | B1: Component | C1: Rate | D1: Discount
A2: Labour | B2: Labour
A3: Misc. | B3: Misc.
A4: Labour | B4: Lathe Work | C4: 150
A5: Labour | B5: CNC work | C5: 650
A6: Labour | B6: Fabrication
A7: Polish | B7: Water PU Polish - Hand | C7: 100
A8: Polish | B8: Water PU polish - Spray | C8: 160
A9: Labour | B9: Swing Fixing | C9: 4000
A10: Material | B10: Fabric | C10: 1200
A11: Material | B11: Leatherite | C11: 800
A12: Material | B12: Leather
A13: Material | B13: Bison Board | C13: 2232
A14: Material | B14: 19mm plywood | C14: 1800
A15: Material | B15: 19mm plywood - Mikasa or Green | C15: 3200
A16: Material | B16: 12mm plywood | C16: 1600
A17: Material | B17: 12mm plywood - Mikasa or Green | C17: 2600
A18: Material | B18: 6mm plywood | C18: 1500
A19: Material | B19: 6mm plywood - Mikasa or green | C19: 1600
A20: Material | B20: Teak Laminate | C20: 750
A21: Material | B21: Teak Veneer | C21: 3500
A22: Material | B22: Teak beading | C22: 35
A23: Material | B23: Fevicol | C23: 280
A24: Material | B24: Edge Banding | C24: 15
... A29: Material | B29: 20in channel - Ebco | C29: 600
A30: Material | B30: 20in channel - Hettich | C30: =E30-(E30*D30) -> 896.52 | D30: 0.38 | E30: 1446
A31: Material | B31: 18in channel - Ebco
A32: Material | B32: 18in channel - Hettich | C32: =E32-(E32*D32) -> 863.04 | D32: 0.38 | E32: 1392
A33: Material | B33: 16in channel - Ebco | C33: 500
A34: Material | B34: 16in channel - Hettich | C34: =E34-(E34*D34) -> 828.94 | D34: 0.38 | E34: 1337
A35: Material | B35: 14in channel - Ebco | C35: 450
A36: Material | B36: 14in channel - Hettich | C36: =E36-(E36*D36) -> 761.98 | D36: 0.38 | E36: 1229
A37: Material | B37: 12in channel - Ebco | C37: 400
A38: Material | B38: 12in channel - Hettich | C38: 500 | D38: 0.38 | E38: 1283
A39: Material | B39: 12in Channel - PTO - Hettich | C39: 750 | D39: 0.4 | E39: 1230
A40: Material | B40: 16in Channel - PTO - Hettich | C40: 810 | D40: 0.4 | E40: 1337
A41: Material | B41: 18in Channel - PTO - Hettich | C41: 850 | D41: 0.4 | E41: 1392
A42: Material | B42: 20in Channel - PTO - Hettich | C42: 900 | D42: 0.4 | E42: 1446
A43: Material | B43: 0 Crank hinge | C43: 230
A44: Material | B44: 8 Crank hinge | C44: 250
...

Sheet Sheet5
A1: =MasterSummary!A1 -> Furniture | B1: =MasterSummary!U1 -> Item Rate
A2: =MasterSummary!A2 -> Barstool 01 B1 | B2: =MasterSummary!U2 -> 19000
A3: =MasterSummary!A3 -> Barstool 03 A1 | B3: =MasterSummary!U3 -> 20000
A4: =MasterSummary!A4 -> Barstool 11 A1 | B4: =MasterSummary!U4 -> 27000
A5: =MasterSummary!A5 -> Bed 01 A1 | B5: =MasterSummary!U5 -> 105000
A6: =MasterSummary!A6 -> Bed 04 A1 | B6: =MasterSummary!U6 -> 117000
A7: =MasterSummary!A7 -> Bed 27 A1 | B7: =MasterSummary!U7 -> 146000
A8: =MasterSummary!A8 -> Bed 47 A1 | B8: =MasterSummary!U8 -> 103000
A9: =MasterSummary!A9 -> Bench 03 A1 | B9: =MasterSummary!U9 -> 25000
A10: =MasterSummary!A10 -> Bench 14 A1 | B10: =MasterSummary!U10 -> 50000
A11: =MasterSummary!A11 -> Bench 20 B1 | B11: =MasterSummary!U11 -> 38000
A12: =MasterSummary!A12 -> Centre Table 02 A1 | B12: =MasterSummary!U12 -> 22000
... A45: =MasterSummary!A45 -> Bed 27 B1 | B45: =MasterSummary!U45 -> 135000
